nohup: ignoring input
Using TensorFlow backend.
/home/top/.pyenv/versions/3.7.12/lib/python3.7/site-packages/numpy/lib/function_base.py:2530: RuntimeWarning: invalid value encountered in true_divide
  c /= stddev[:, None]
/home/top/.pyenv/versions/3.7.12/lib/python3.7/site-packages/numpy/lib/function_base.py:2531: RuntimeWarning: invalid value encountered in true_divide
  c /= stddev[None, :]
WARNING:tensorflow:From /home/top/.pyenv/versions/3.7.12/lib/python3.7/site-packages/tensorflow_core/python/ops/init_ops.py:97: calling GlorotUniform.__init__ (from tensorflow.python.ops.init_ops) with dtype is deprecated and will be removed in a future version.
Instructions for updating:
Call initializer instance with the dtype argument instead of passing it to the constructor
WARNING:tensorflow:From /home/top/.pyenv/versions/3.7.12/lib/python3.7/site-packages/tensorflow_core/python/ops/init_ops.py:97: calling Zeros.__init__ (from tensorflow.python.ops.init_ops) with dtype is deprecated and will be removed in a future version.
Instructions for updating:
Call initializer instance with the dtype argument instead of passing it to the constructor
WARNING:tensorflow:From /home/top/.pyenv/versions/3.7.12/lib/python3.7/site-packages/tensorflow_core/python/ops/init_ops.py:97: calling Ones.__init__ (from tensorflow.python.ops.init_ops) with dtype is deprecated and will be removed in a future version.
Instructions for updating:
Call initializer instance with the dtype argument instead of passing it to the constructor
WARNING:tensorflow:From /home/top/.pyenv/versions/3.7.12/lib/python3.7/site-packages/tensorflow_core/python/ops/resource_variable_ops.py:1630: calling BaseResourceVariable.__init__ (from tensorflow.python.ops.resource_variable_ops) with constraint is deprecated and will be removed in a future version.
Instructions for updating:
If using Keras pass *_constraint arguments to layers.
2021-11-23 11:42:12.326117: I tensorflow/core/platform/cpu_feature_guard.cc:142] Your CPU supports instructions that this TensorFlow binary was not compiled to use: AVX2 FMA
2021-11-23 11:42:12.382099: I tensorflow/core/platform/profile_utils/cpu_utils.cc:94] CPU Frequency: 1996035000 Hz
2021-11-23 11:42:12.389390: I tensorflow/compiler/xla/service/service.cc:168] XLA service 0x6a901b0 initialized for platform Host (this does not guarantee that XLA will be used). Devices:
2021-11-23 11:42:12.389469: I tensorflow/compiler/xla/service/service.cc:176]   StreamExecutor device (0): Host, Default Version
/home/top/.pyenv/versions/3.7.12/lib/python3.7/site-packages/keras/engine/training.py:297: UserWarning: Discrepancy between trainable weights and collected trainable weights, did you set `model.trainable` without calling `model.compile` after ?
  'Discrepancy between trainable weights and collected trainable'
WARNING:tensorflow:From /home/top/.pyenv/versions/3.7.12/lib/python3.7/site-packages/tensorflow_core/python/ops/math_grad.py:1424: where (from tensorflow.python.ops.array_ops) is deprecated and will be removed in a future version.
Instructions for updating:
Use tf.where in 2.0, which has the same broadcast rule as np.where
WARNING:tensorflow:From /home/top/.pyenv/versions/3.7.12/lib/python3.7/site-packages/keras/backend/tensorflow_backend.py:422: The name tf.global_variables is deprecated. Please use tf.compat.v1.global_variables instead.

2021-11-23 11:50:54.526047: E tensorflow/core/grappler/optimizers/dependency_optimizer.cc:697] Iteration = 0, topological sort failed with message: The graph couldn't be sorted in topological order.
2021-11-23 11:50:54.565773: E tensorflow/core/grappler/optimizers/dependency_optimizer.cc:697] Iteration = 1, topological sort failed with message: The graph couldn't be sorted in topological order.
2021-11-23 11:50:54.750594: E tensorflow/core/grappler/optimizers/meta_optimizer.cc:533] model_pruner failed: Invalid argument: MutableGraphView::MutableGraphView error: node 'loss_2/model_2_loss/mean_squared_error/weighted_loss/concat' has self cycle fanin 'loss_2/model_2_loss/mean_squared_error/weighted_loss/concat'.
2021-11-23 11:50:55.358752: E tensorflow/core/grappler/optimizers/meta_optimizer.cc:533] remapper failed: Invalid argument: MutableGraphView::MutableGraphView error: node 'loss_2/model_2_loss/mean_squared_error/weighted_loss/concat' has self cycle fanin 'loss_2/model_2_loss/mean_squared_error/weighted_loss/concat'.
2021-11-23 11:50:55.446065: E tensorflow/core/grappler/optimizers/meta_optimizer.cc:533] arithmetic_optimizer failed: Invalid argument: The graph couldn't be sorted in topological order.
2021-11-23 11:50:55.510153: E tensorflow/core/grappler/optimizers/dependency_optimizer.cc:697] Iteration = 0, topological sort failed with message: The graph couldn't be sorted in topological order.
2021-11-23 11:50:55.586207: E tensorflow/core/grappler/optimizers/dependency_optimizer.cc:697] Iteration = 1, topological sort failed with message: The graph couldn't be sorted in topological order.
/home/top/.pyenv/versions/3.7.12/lib/python3.7/site-packages/keras/engine/training.py:297: UserWarning: Discrepancy between trainable weights and collected trainable weights, did you set `model.trainable` without calling `model.compile` after ?
  'Discrepancy between trainable weights and collected trainable'
/home/top/.pyenv/versions/3.7.12/lib/python3.7/site-packages/keras/engine/training.py:297: UserWarning: Discrepancy between trainable weights and collected trainable weights, did you set `model.trainable` without calling `model.compile` after ?
  'Discrepancy between trainable weights and collected trainable'
/home/top/.pyenv/versions/3.7.12/lib/python3.7/site-packages/keras/engine/training.py:297: UserWarning: Discrepancy between trainable weights and collected trainable weights, did you set `model.trainable` without calling `model.compile` after ?
  'Discrepancy between trainable weights and collected trainable'
pca.n_components_:  23
df_pca.shape:  (281199, 23)
X_ae.shape:  (281199, 26)
Epoch: 1/1, [Dx loss: [ 1.0843887  -0.1937654   0.09085207  0.11873022]] [Dz loss: [ -9.236263    1.9023718 -16.252598    0.5113951]] [G loss: [21.101782   -0.09900256 20.588852    0.06119335]]
(56117, 100, 23)
Traceback (most recent call last):
  File "driver.py", line 71, in <module>
    
  File "driver.py", line 50, in main
    df_pca["Normal/Attack"] = y
  File "/home/top/anomaly_detection_in_indestrial_control_systems/tulog/optimum.py", line 258, in run_tadgan
    fout.write(str(score) + " / " + str(overall_count) + "  " + "window_size-" + str(window) + "_epoch-200_learning_rate-0.0005_latent_dim-" + str(dim) + "_batch_size-512_comb-mult_" + techniques)
NameError: name 'window' is not defined
